<mujoco model="ant">
    <compiler angle="degree" coordinate="local" inertiafromgeom="true"/>
    <option integrator="RK4" timestep="0.01"/>
    <custom>
        <numeric data="0.0 0.0 0.55 1.0 0.0 0.0 0.0 0.0 1.0 0.0 -1.0 0.0 -1.0 0.0 1.0" name="init_qpos"/>
    </custom>
    <default>
        <joint armature="1" damping="1" limited="true"/>
        <geom conaffinity="0" condim="3" density="5.0" friction="1 0.5 0.5" margin="0.01" rgba="0.8 0.6 0.4 1"/>
    </default>
    <asset>
        <texture builtin="gradient" height="100" rgb1="1 1 1" rgb2="0 0 0" type="skybox" width="100"/>
        <texture builtin="flat" height="1278" mark="cross" markrgb="1 1 1" name="texgeom" random="0.01"
                 rgb1="0.8 0.6 0.4" rgb2="0.8 0.6 0.4" type="cube" width="127"/>
        <texture builtin="checker" height="100" name="texplane" rgb1="0 0 0" rgb2="0.8 0.8 0.8" type="2d" width="100"/>
        <material name="MatPlane" reflectance="0.5" shininess="1" specular="1" texrepeat="60 60" texture="texplane"/>
        <material name="geom" texture="texgeom" texuniform="true"/>
        <hfield name="terrain_hfield" file="generated_terrain.png" size="50 50 {{HFIELD_HEIGHT}} 0.1"/>
        <!--    <hfield name="terrain_hfield" nrow="1000" ncol="1000" size="40 40 1 0.1"/>-->
    </asset>
    <worldbody>
        <light cutoff="100" diffuse="1 1 1" dir="-0 0 -1.3" directional="true" exponent="1" pos="0 0 1.3"
               specular=".1 .1 .1"/>

        <!--    Floor-->
        <!--    <geom conaffinity="1" condim="3" material="MatPlane" name="floor" pos="0 0 0" rgba="0.8 0.9 0.8 1" size="200 200 200" euler="0 0 0" type="plane"/>-->

        <!--    Terrain-->
        <geom conaffinity="1" condim="3" material="MatPlane" hfield="terrain_hfield" name="terrain"
              pos="{{HFIELD_XOFFSET}} 0 0" rgba="0.5 0.5 0.5 1" euler="0 0 0" type="hfield"/>


        <body name="torso" pos="0 0 {{START_HEIGHT}}">
            <camera name="track" mode="trackcom" pos="0 -10 1.3" xyaxes="1 0 0 0 0 1"/>
            <geom name="torso_geom" pos="0 0 0" size="0.25" type="sphere"/>

            <site name="rangefinder_torso" type="sphere" pos="0 0 -0.2" size="0.03" euler="180 0 0" rgba="0 0 1 .7"/>
            <site name="torso_site" type="sphere" pos="0 0 0" size="0.03" euler="0 0 0" rgba="0 0 1 .7"/>

            <joint armature="0" damping="0" limited="false" margin="0.01" name="root" pos="0 0 0" type="free"/>
            <body name="front_left_leg" pos="0 0 0">
                <geom fromto="0.0 0.0 0.0 0.2 0.2 0.0" name="aux_1_geom" size="0.08" type="capsule"/>
                <body name="aux_1" pos="0.2 0.2 0">
                    <joint axis="0 0 1" name="hip_1" pos="0.0 0.0 0.0" range="-30 30" type="hinge"/>
                    <geom fromto="0.0 0.0 0.0 0.2 0.2 0.0" name="left_leg_geom" size="0.08" type="capsule"/>
                    <body pos="0.2 0.2 0">
                        <joint axis="-1 1 0" name="ankle_1" pos="0.0 0.0 0.0" range="30 70" type="hinge"/>
                        <geom fromto="0.0 0.0 0.0 0.4 0.4 0.0" name="left_ankle_geom" size="0.08" type="capsule"/>
                        <site name="rangefinder_frontleft1" type="sphere" pos=".4 .4 0" size="0.03" zaxis="1 0 0 "
                              rgba="0 0 1 .7"/>
                        <site name="rangefinder_frontleft2" type="sphere" pos=".4 .4 0" size="0.03" zaxis="0 1 0 "
                              rgba="0 0 1 .7"/>
                        <site name="rangefinder_frontleft3" type="sphere" pos=".4 .4 0" size="0.03" zaxis="1 1 1 "
                              rgba="0 0 1 .7"/>
                        <site name="rangefinder_frontleft4" type="sphere" pos=".4 .4 0" size="0.03" zaxis="1 1 -1 "
                              rgba="0 0 1 .7"/>

                    </body>
                </body>
            </body>
            <body name="front_right_leg" pos="0 0 0">
                <geom fromto="0.0 0.0 0.0 -0.2 0.2 0.0" name="aux_2_geom" size="0.08" type="capsule"/>
                <body name="aux_2" pos="-0.2 0.2 0">
                    <joint axis="0 0 1" name="hip_2" pos="0.0 0.0 0.0" range="-30 30" type="hinge"/>
                    <geom fromto="0.0 0.0 0.0 -0.2 0.2 0.0" name="right_leg_geom" size="0.08" type="capsule"/>
                    <body pos="-0.2 0.2 0">
                        <joint axis="1 1 0" name="ankle_2" pos="0.0 0.0 0.0" range="-70 -30" type="hinge"/>
                        <geom fromto="0.0 0.0 0.0 -0.4 0.4 0.0" name="right_ankle_geom" size="0.08" type="capsule"/>
                        <site name="rangefinder_frontright1" type="sphere" pos="-.4 .4 0" size="0.03" zaxis="-1 0 0 "
                              rgba="0 0 1 .7"/>
                        <site name="rangefinder_frontright2" type="sphere" pos="-.4 .4 0" size="0.03" zaxis="-0 1 0 "
                              rgba="0 0 1 .7"/>
                        <site name="rangefinder_frontright3" type="sphere" pos="-.4 .4 0" size="0.03" zaxis="-1 1 1 "
                              rgba="0 0 1 .7"/>
                        <site name="rangefinder_frontright4" type="sphere" pos="-.4 .4 0" size="0.03" zaxis="-1 1 -1 "
                              rgba="0 0 1 .7"/>


                    </body>
                </body>
            </body>
            <body name="back_leg" pos="0 0 0">
                <geom fromto="0.0 0.0 0.0 -0.2 -0.2 0.0" name="aux_3_geom" size="0.08" type="capsule"/>
                <body name="aux_3" pos="-0.2 -0.2 0">
                    <joint axis="0 0 1" name="hip_3" pos="0.0 0.0 0.0" range="-30 30" type="hinge"/>
                    <geom fromto="0.0 0.0 0.0 -0.2 -0.2 0.0" name="back_leg_geom" size="0.08" type="capsule"/>
                    <body pos="-0.2 -0.2 0">
                        <joint axis="-1 1 0" name="ankle_3" pos="0.0 0.0 0.0" range="-70 -30" type="hinge"/>
                        <geom fromto="0.0 0.0 0.0 -0.4 -0.4 0.0" name="third_ankle_geom" size="0.08" type="capsule"/>
                        <site name="rangefinder_backleft1" type="sphere" pos="-.4 -.4 0" size="0.03" zaxis="-1 -0 0 "
                              rgba="0 0 1 .7"/>
                        <site name="rangefinder_backleft2" type="sphere" pos="-.4 -.4 0" size="0.03" zaxis="-0 -1 0 "
                              rgba="0 0 1 .7"/>
                        <site name="rangefinder_backleft3" type="sphere" pos="-.4 -.4 0" size="0.03" zaxis="-1 -1 1 "
                              rgba="0 0 1 .7"/>
                        <site name="rangefinder_backleft4" type="sphere" pos="-.4 -.4 0" size="0.03" zaxis="-1 -1 -1 "
                              rgba="0 0 1 .7"/>

                    </body>
                </body>
            </body>
            <body name="right_back_leg" pos="0 0 0">
                <geom fromto="0.0 0.0 0.0 0.2 -0.2 0.0" name="aux_4_geom" size="0.08" type="capsule"/>
                <body name="aux_4" pos="0.2 -0.2 0">
                    <joint axis="0 0 1" name="hip_4" pos="0.0 0.0 0.0" range="-30 30" type="hinge"/>
                    <geom fromto="0.0 0.0 0.0 0.2 -0.2 0.0" name="rightback_leg_geom" size="0.08" type="capsule"/>
                    <body pos="0.2 -0.2 0">
                        <joint axis="1 1 0" name="ankle_4" pos="0.0 0.0 0.0" range="30 70" type="hinge"/>
                        <geom fromto="0.0 0.0 0.0 0.4 -0.4 0.0" name="fourth_ankle_geom" size="0.08" type="capsule"/>
                        <site name="rangefinder_backright1" type="sphere" pos=".4 -.4 0" size="0.03" zaxis="1 -0 0 "
                              rgba="0 0 1 .7"/>
                        <site name="rangefinder_backright2" type="sphere" pos=".4 -.4 0" size="0.03" zaxis="0 -1 0 "
                              rgba="0 0 1 .7"/>
                        <site name="rangefinder_backright3" type="sphere" pos=".4 -.4 0" size="0.03" zaxis="1 -1 1 "
                              rgba="0 0 1 .7"/>
                        <site name="rangefinder_backright4" type="sphere" pos=".4 -.4 0" size="0.03" zaxis="1 -1 -1 "
                              rgba="0 0 1 .7"/>

                    </body>
                </body>
            </body>
        </body>
    </worldbody>

    <actuator>
        <motor ctrllimited="true" ctrlrange="-1.0 1.0" joint="hip_4" gear="150"/>
        <motor ctrllimited="true" ctrlrange="-1.0 1.0" joint="ankle_4" gear="150"/>
        <motor ctrllimited="true" ctrlrange="-1.0 1.0" joint="hip_1" gear="150"/>
        <motor ctrllimited="true" ctrlrange="-1.0 1.0" joint="ankle_1" gear="150"/>
        <motor ctrllimited="true" ctrlrange="-1.0 1.0" joint="hip_2" gear="150"/>
        <motor ctrllimited="true" ctrlrange="-1.0 1.0" joint="ankle_2" gear="150"/>
        <motor ctrllimited="true" ctrlrange="-1.0 1.0" joint="hip_3" gear="150"/>
        <motor ctrllimited="true" ctrlrange="-1.0 1.0" joint="ankle_3" gear="150"/>
    </actuator>

    <sensor>
        <velocimeter name="sensor_velocimeter" site="torso_site"/>
        <gyro name="sensor_gyro" site="torso_site"/>
        <accelerometer name="sensor_accel" site="torso_site"/>
        <rangefinder name="sensor_rangefinder_torso" site="rangefinder_torso"/>
        <rangefinder name="sensor_rangefinder_frontleft1" site="rangefinder_frontleft1"/>
        <rangefinder name="sensor_rangefinder_frontleft2" site="rangefinder_frontleft2"/>
        <rangefinder name="sensor_rangefinder_frontleft3" site="rangefinder_frontleft3"/>
        <rangefinder name="sensor_rangefinder_frontleft4" site="rangefinder_frontleft4"/>

        <rangefinder name="sensor_rangefinder_frontright1" site="rangefinder_frontright1"/>
        <rangefinder name="sensor_rangefinder_frontright2" site="rangefinder_frontright2"/>
        <rangefinder name="sensor_rangefinder_frontright3" site="rangefinder_frontright3"/>
        <rangefinder name="sensor_rangefinder_frontright4" site="rangefinder_frontright4"/>

        <rangefinder name="sensor_rangefinder_backleft1" site="rangefinder_backleft1"/>
        <rangefinder name="sensor_rangefinder_backleft2" site="rangefinder_backleft2"/>
        <rangefinder name="sensor_rangefinder_backleft3" site="rangefinder_backleft3"/>
        <rangefinder name="sensor_rangefinder_backleft4" site="rangefinder_backleft4"/>

        <rangefinder name="sensor_rangefinder_backright1" site="rangefinder_backright1"/>
        <rangefinder name="sensor_rangefinder_backright2" site="rangefinder_backright2"/>
        <rangefinder name="sensor_rangefinder_backright3" site="rangefinder_backright3"/>
        <rangefinder name="sensor_rangefinder_backright4" site="rangefinder_backright4"/>

    </sensor>
</mujoco>
