<mujoco model="cylinder">
    <compiler angle="degree" coordinate="local" inertiafromgeom="true"/>
    <option integrator="RK4" timestep="0.01"/>
    <custom>
        <numeric data="0.0 0.0 0.55 1.0 0.0 0.0 0.0 0.0 1.0 0.0 -1.0 0.0 -1.0 0.0 1.0" name="init_qpos"/>
    </custom>
    <default>
        <joint armature="1" damping="1" limited="true"/>
        <geom conaffinity="0" condim="3" density="5.0" friction="1 0.5 0.5" margin="0.01" rgba="0.8 0.6 0.4 1"/>
    </default>
    <asset>
        <texture builtin="gradient" height="100" rgb1="1 1 1" rgb2="0 0 0" type="skybox" width="100"/>
        <texture builtin="flat" height="1278" mark="cross" markrgb="1 1 1" name="texgeom" random="0.01"
                 rgb1="0.8 0.6 0.4" rgb2="0.8 0.6 0.4" type="cube" width="127"/>
        <texture builtin="checker" height="100" name="texplane" rgb1="0 0 0" rgb2="0.8 0.8 0.8" type="2d" width="100"/>
        <material name="MatPlane" reflectance="0.5" shininess="1" specular="1" texrepeat="60 60" texture="texplane"/>
        <material name="geom" texture="texgeom" texuniform="true"/>
        <hfield name="terrain_hfield" file="generated_terrain.png" size="50 50 {{HFIELD_HEIGHT}} 0.1"/>
        <!--    <hfield name="terrain_hfield" nrow="1000" ncol="1000" size="40 40 1 0.1"/>-->
    </asset>
    <worldbody>
        <light cutoff="100" diffuse="1 1 1" dir="-0 0 -1.3" directional="true" exponent="1" pos="0 0 1.3"
               specular=".1 .1 .1"/>

        <!--    Floor-->
        <!--    <geom conaffinity="1" condim="3" material="MatPlane" name="floor" pos="0 0 0" rgba="0.8 0.9 0.8 1" size="200 200 200" euler="0 0 0" type="plane"/>-->

        <!--    Terrain-->
        <geom conaffinity="1" condim="3" material="MatPlane" hfield="terrain_hfield" name="terrain"
              pos="{{HFIELD_XOFFSET}} 0 0" rgba="0.5 0.5 0.5 1" euler="0 0 0" type="hfield"/>


        <body name="torso" pos="0 0 {{START_HEIGHT}}">
            <camera name="track" mode="trackcom" pos="0 -10 1.3" xyaxes="1 0 0 0 0 1"/>
            <geom name="torso_geom" pos="0 0 0" size="0.1 .2" type="capsule"/>
            <site name="torso_site" type="sphere" pos="0 0 0" size="0.03" euler="0 0 0" rgba="0 0 1 .7"/>
            <joint armature="0" damping="0" limited="false" margin="0.01" name="root" pos="0 0 0" type="free"/>
            <body name="a" pos="0.277 0.116 0">
             <joint name="a" pos="0 0 0" axis="1 0 0" limited="true" range="-9.42 9.42"/>
                  <geom size="0.05 0.05" pos="-0.227 -0.116 0" quat="0.707107 0 0.707107 0" type="cylinder"
                  rgba="0.7 0.7 0.7 1"/>
            </body>
        </body>
    </worldbody>

    <actuator>
        <motor ctrllimited="true" ctrlrange="-1.0 1.0" joint="a" gear="150"/>
<!--        <motor ctrllimited="true" ctrlrange="-1.0 1.0" joint="ankle_4" gear="150"/>-->
<!--        <motor ctrllimited="true" ctrlrange="-1.0 1.0" joint="hip_1" gear="150"/>-->
<!--        <motor ctrllimited="true" ctrlrange="-1.0 1.0" joint="ankle_1" gear="150"/>-->
<!--        <motor ctrllimited="true" ctrlrange="-1.0 1.0" joint="hip_2" gear="150"/>-->
<!--        <motor ctrllimited="true" ctrlrange="-1.0 1.0" joint="ankle_2" gear="150"/>-->
<!--        <motor ctrllimited="true" ctrlrange="-1.0 1.0" joint="hip_3" gear="150"/>-->
<!--        <motor ctrllimited="true" ctrlrange="-1.0 1.0" joint="ankle_3" gear="150"/>-->
    </actuator>

<!--    <sensor>-->
<!--        <velocimeter name="sensor_velocimeter" site="torso_site"/>-->
<!--        <gyro name="sensor_gyro" site="torso_site"/>-->
<!--        <accelerometer name="sensor_accel" site="torso_site"/>-->
<!--    </sensor>-->
</mujoco>
