<mujoco model="NaoH25V50">
    <compiler angle="radian" meshdir="/home/thomas/uva/scriptie/walking/ant/worlds/"/>
    <asset>
        <texture builtin="gradient" height="100" rgb1="1 1 1" rgb2="0 0 0" type="skybox" width="100"/>
        <texture builtin="flat" height="1278" mark="cross" markrgb="1 1 1" name="texgeom" random="0.01"
                 rgb1="0.8 0.6 0.4" rgb2="0.8 0.6 0.4" type="cube" width="127"/>
        <texture builtin="checker" height="100" name="texplane" rgb1="0 0 0" rgb2="0.8 0.8 0.8" type="2d" width="100"/>
        <material name="MatPlane" reflectance="0.5" shininess="1" specular="1" texrepeat="60 60" texture="texplane"/>
        <material name="geom" texture="texgeom" texuniform="true"/>
        <hfield name="terrain_hfield" file="/tmp/generated_terrain.png" size="50 50 {{HFIELD_HEIGHT}} 1"/>
    </asset>


    <default>
        <joint armature=".1" damping=".1"/>
        <geom conaffinity="0" condim="3" density="5.0" friction="1 0.5 0.5" margin="0.01" rgba="0.8 0.6 0.4 1"/>
    </default>


    <size njmax="500" nconmax="100"/>
    <asset>
        <mesh name="Torso" file="nao/Torso.stl" scale="0.1 0.1 0.1"/>
        <mesh name="HeadYaw" file="nao/HeadYaw.stl" scale="0.1 0.1 0.1"/>
        <mesh name="HeadPitch" file="nao/HeadPitch.stl" scale="0.1 0.1 0.1"/>
        <mesh name="LHipYawPitch" file="nao/LHipYawPitch.stl" scale="0.1 0.1 0.1"/>
        <mesh name="LHipRoll" file="nao/LHipRoll.stl" scale="0.1 0.1 0.1"/>
        <mesh name="LHipPitch" file="nao/LHipPitch.stl" scale="0.1 0.1 0.1"/>
        <mesh name="LKneePitch" file="nao/LKneePitch.stl" scale="0.1 0.1 0.1"/>
        <mesh name="LAnklePitch" file="nao/LAnklePitch.stl" scale="0.1 0.1 0.1"/>
        <mesh name="LAnkleRoll" file="nao/LAnkleRoll.stl" scale="0.1 0.1 0.1"/>
        <mesh name="RHipYawPitch" file="nao/RHipYawPitch.stl" scale="0.1 0.1 0.1"/>
        <mesh name="RHipRoll" file="nao/RHipRoll.stl" scale="0.1 0.1 0.1"/>
        <mesh name="RHipPitch" file="nao/RHipPitch.stl" scale="0.1 0.1 0.1"/>
        <mesh name="RKneePitch" file="nao/RKneePitch.stl" scale="0.1 0.1 0.1"/>
        <mesh name="RAnklePitch" file="nao/RAnklePitch.stl" scale="0.1 0.1 0.1"/>
        <mesh name="RAnkleRoll" file="nao/RAnkleRoll.stl" scale="0.1 0.1 0.1"/>
        <mesh name="LShoulderPitch" file="nao/LShoulderPitch.stl" scale="0.1 0.1 0.1"/>
        <mesh name="LShoulderRoll" file="nao/LShoulderRoll.stl" scale="0.1 0.1 0.1"/>
        <mesh name="LElbowRoll" file="nao/LElbowRoll.stl" scale="0.1 0.1 0.1"/>
        <mesh name="LWristYaw" file="nao/LWristYaw.stl" scale="0.1 0.1 0.1"/>
        <mesh name="LFinger21" file="nao/LFinger21.stl" scale="0.1 0.1 0.1"/>
        <mesh name="LFinger22" file="nao/LFinger22.stl" scale="0.1 0.1 0.1"/>
        <mesh name="LFinger23" file="nao/LFinger23.stl" scale="0.1 0.1 0.1"/>
        <mesh name="LFinger11" file="nao/LFinger11.stl" scale="0.1 0.1 0.1"/>
        <mesh name="LFinger12" file="nao/LFinger12.stl" scale="0.1 0.1 0.1"/>
        <mesh name="LFinger13" file="nao/LFinger13.stl" scale="0.1 0.1 0.1"/>
        <mesh name="LThumb1" file="nao/LThumb1.stl" scale="0.1 0.1 0.1"/>
        <mesh name="LThumb2" file="nao/LThumb2.stl" scale="0.1 0.1 0.1"/>
        <mesh name="RShoulderPitch" file="nao/RShoulderPitch.stl" scale="0.1 0.1 0.1"/>
        <mesh name="RShoulderRoll" file="nao/RShoulderRoll.stl" scale="0.1 0.1 0.1"/>
        <mesh name="RElbowRoll" file="nao/RElbowRoll.stl" scale="0.1 0.1 0.1"/>
        <mesh name="RWristYaw" file="nao/RWristYaw.stl" scale="0.1 0.1 0.1"/>
        <mesh name="RFinger21" file="nao/RFinger21.stl" scale="0.1 0.1 0.1"/>
        <mesh name="RFinger22" file="nao/RFinger22.stl" scale="0.1 0.1 0.1"/>
        <mesh name="RFinger23" file="nao/RFinger23.stl" scale="0.1 0.1 0.1"/>
        <mesh name="RFinger11" file="nao/RFinger11.stl" scale="0.1 0.1 0.1"/>
        <mesh name="RFinger12" file="nao/RFinger12.stl" scale="0.1 0.1 0.1"/>
        <mesh name="RFinger13" file="nao/RFinger13.stl" scale="0.1 0.1 0.1"/>
        <mesh name="RThumb1" file="nao/RThumb1.stl" scale="0.1 0.1 0.1"/>
        <mesh name="RThumb2" file="nao/RThumb2.stl" scale="0.1 0.1 0.1"/>
    </asset>

    <worldbody>
        <light cutoff="100" diffuse="1 1 1" dir="-0 0 -1.3" directional="true" exponent="1" pos="0 0 1.3"
               specular=".1 .1 .1"/>

        <!--    Terrain-->
        <geom conaffinity="1" condim="3" material="MatPlane" hfield="terrain_hfield" name="terrain"
              pos="{{HFIELD_XOFFSET}} 0 0" rgba="0.5 0.5 0.5 1" euler="0 0 0" type="hfield"/>


        <!--       REPLACED mass\=\"0\" mass\=\"0.001\"-->
        <!--       REPLACED diaginertia\=\"0 0 0\" diaginertia\=\"0.001 0.001 0.001\" -->
        <body name="base_link" pos="0 0 .35">
            <joint armature="0" damping="0" limited="false" margin="0.01" name="root" pos="0 0 0" type="free"/>
            <camera name="track" mode="trackcom" pos="0 -3 0.3" xyaxes="1 0 0 0 0 1"/>
            <inertial pos="0 0 0" mass="0.001" diaginertia="0.001 0.001 0.001"/>

            <body name="torso" pos="0 0 0">
                <inertial pos="-0.00413 0 0.04342" quat="0.9992 -0.00993848 0.0113353 0.0370387" mass="1.04956"
                          diaginertia="0.00308544 0.00288295 0.00159112"/>
                                <geom type="mesh" mesh="Torso"/>
                <site name="rangefinder_torso" type="sphere" pos="0 0 -0.2" size="0.03" euler="180 0 0"
                      rgba="0 0 1 .7"/>
<!--                TODO MAYBE PLACE AT PELVIS?-->
                <site name="torso_site" type="sphere" pos="0 0 0" size="0.03" euler="0 0 0" rgba="0 0 1 .7"/>

                <body name="Neck" pos="0 0 0.1265">
                    <inertial pos="-1e-05 0 -0.02742" quat="0.70765 -0.00173495 0.00151894 0.706559" mass="0.07842"
                              diaginertia="1.70396e-05 1.60324e-05 5.53348e-06"/>
                    <joint name="HeadYaw" pos="0 0 0" axis="0 0 1" limited="true" range="-2.08567 2.08567"/>
                                        <geom type="mesh" mesh="HeadYaw"/>
                    <body name="Head" pos="0 0 0">
                        <inertial pos="-0.00112 0 0.05258" quat="0.463877 0.585354 -0.492966 0.446277" mass="0.60533"
                                  diaginertia="0.000990592 0.000957952 0.000811033"/>
                        <joint name="HeadPitch" pos="0 0 0" axis="0 1 0" limited="true" range="-0.671952 0.514872"/>
                                                <geom type="mesh" mesh="HeadPitch"/>
                        <body name="gaze" pos="0.05871 0 0.06364">
                            <inertial pos="0.05871 0 0.06364" mass="0.001" diaginertia="0.001 0.001 0.001"/>
                        </body>
                        <body name="HeadTouchFront_frame" pos="0.0312 0 0.1014" quat="0.82924 0 -0.558893 0">
                            <inertial pos="0.0312 0 0.1014" quat="0.82924 0 -0.558893 0" mass="0.001"
                                      diaginertia="0.001 0.001 0.001"/>
                        </body>
                        <body name="CameraBottom_frame" pos="0.05071 0 0.01774" quat="0.940585 0 0.339559 0">
                            <inertial pos="0.05071 0 0.01774" quat="0.940585 0 0.339559 0" mass="0.001"
                                      diaginertia="0.001 0.001 0.001"/>
                            <body name="CameraBottom_optical_frame" pos="0 0 0" quat="0.5 -0.5 0.5 -0.5">
                                <inertial pos="0 0 0" quat="0.5 -0.5 0.5 -0.5" mass="0.001"
                                          diaginertia="0.001 0.001 0.001"/>
                            </body>
                        </body>
                        <body name="CameraTop_frame" pos="0.05871 0 0.06364" quat="0.999945 0 0.0104716 0">
                            <inertial pos="0.05871 0 0.06364" quat="0.999945 0 0.0104716 0" mass="0.001"
                                      diaginertia="0.001 0.001 0.001"/>
                            <body name="CameraTop_optical_frame" pos="0 0 0" quat="0.5 -0.5 0.5 -0.5">
                                <inertial pos="0 0 0" quat="0.5 -0.5 0.5 -0.5" mass="0.001"
                                          diaginertia="0.001 0.001 0.001"/>
                            </body>
                        </body>
                        <body name="LInfraRed_frame" pos="0.0441 0.0257 0.0466">
                            <inertial pos="0.0441 0.0257 0.0466" mass="0.001" diaginertia="0.001 0.001 0.001"/>
                        </body>
                        <body name="HeadTouchRear_frame" pos="-0.0257 0 0.1045"
                              quat="0.618313 2.22395e-07 -0.785932 -2.22395e-07">
                            <inertial pos="-0.0257 0 0.1045" quat="0.618313 2.22395e-07 -0.785932 -2.22395e-07"
                                      mass="0.001"
                                      diaginertia="0.001 0.001 0.001"/>
                        </body>
                        <body name="HeadTouchMiddle_frame" pos="0.001 0 0.1099"
                              quat="0.707105 5.93571e-12 -0.707109 -5.93571e-12">
                            <inertial pos="0.001 0 0.1099" quat="0.707105 5.93571e-12 -0.707109 -5.93571e-12"
                                      mass="0.001"
                                      diaginertia="0.001 0.001 0.001"/>
                        </body>
                        <body name="RInfraRed_frame" pos="0.0441 -0.0257 0.0466">
                            <inertial pos="0.0441 -0.0257 0.0466" mass="0.001" diaginertia="0.001 0.001 0.001"/>
                        </body>
                    </body>
                </body>
                <body name="LPelvis" pos="0 0.05 -0.085">
                    <inertial pos="-0.00781 -0.01114 0.02661" quat="0.232303 0.656505 0.182148 0.69416" mass="0.06981"
                              diaginertia="5.16414e-05 4.58792e-05 2.32239e-05"/>
                    <joint name="LHipYawPitch" pos="0 0 0" axis="0 0.707107 -0.707107" limited="true"
                           range="-1.14529 0.740718"/>
                                        <geom type="mesh" mesh="LHipYawPitch"/>
                    <body name="LHip" pos="0 0 0">
                        <inertial pos="-0.01549 0.00029 -0.00515" quat="0.453959 0.527953 0.574067 0.430853"
                                  mass="0.14053" diaginertia="6.08587e-05 5.59269e-05 2.22526e-05"/>
                        <joint name="LHipRoll" pos="0 0 0" axis="1 0 0" limited="true" range="-0.379435 0.79046"/>
                                                <geom type="mesh" mesh="LHipRoll"/>
                        <body name="LThigh" pos="0 0 0">
                            <inertial pos="0.00138 0.00221 -0.05373" quat="0.992078 -0.0228023 -0.123519 -0.00190301"
                                      mass="0.38968" diaginertia="0.000524114 0.000465732 0.000286453"/>
                            <joint name="LHipPitch" pos="0 0 0" axis="0 1 0" limited="true" range="-1.53589 0.48398"/>
                                                        <geom type="mesh" mesh="LHipPitch"/>
                            <body name="LTibia" pos="0 0 -0.1">
                                <inertial pos="0.00453 0.00225 -0.04936" quat="0.997907 0.0169027 0.0579417 0.0232071"
                                          mass="0.30142" diaginertia="0.000449928 0.000388139 0.000181704"/>
                                <joint name="LKneePitch" pos="0 0 0" axis="0 1 0" limited="true"
                                       range="-0.0923279 2.11255"/>
                                                                <geom type="mesh" mesh="LKneePitch"/>
                                <body name="LAnklePitch" pos="0 0 -0.1029">
                                    <inertial pos="0.00045 0.00029 0.00685" quat="0.447256 0.548803 0.537287 0.458368"
                                              mass="0.13416" diaginertia="6.79494e-05 5.56016e-05 3.14223e-05"/>
                                    <joint name="LAnklePitch" pos="0 0 0" axis="0 1 0" limited="true"
                                           range="-1.18944 0.922581"/>
                                                                        <geom type="mesh" mesh="LAnklePitch"/>
                                    <body name="l_ankle" pos="0 0 0">
                                        <inertial pos="0.02542 0.0033 -0.03239"
                                                  quat="0.0134359 0.704739 -0.00974829 0.709272" mass="0.17184"
                                                  diaginertia="0.000412861 0.000353308 8.69916e-05"/>
                                        <joint name="LAnkleRoll" pos="0 0 0" axis="1 0 0" limited="true"
                                               range="-0.397761 0.768992"/>
                                                                                <geom type="mesh" mesh="LAnkleRoll"/>
                                        <body name="l_sole" pos="0 0 -0.04511">
                                            <inertial pos="0 0 -0.04511" mass="0.001" diaginertia="0.001 0.001 0.001"/>
                                        </body>
                                        <body name="LFootBumperRight_frame" pos="0.0876 -0.014 -0.0353">
                                            <inertial pos="0.0876 -0.014 -0.0353" mass="0.001"
                                                      diaginertia="0.001 0.001 0.001"/>
                                        </body>
                                        <body name="LFsrFR_frame" pos="0.07025 -0.0231 -0.04511">
                                            <inertial pos="0 0 0" mass="2e-06" diaginertia="1.1e-09 1.1e-09 1.1e-09"/>
                                            <geom size="0.005 0.005 0.0025" type="box"/>
                                        </body>
                                        <body name="LFsrRR_frame" pos="-0.02965 -0.0191 -0.04511">
                                            <inertial pos="0 0 0" mass="2e-06" diaginertia="1.1e-09 1.1e-09 1.1e-09"/>
                                            <geom size="0.005 0.005 0.0025" type="box"/>
                                        </body>
                                        <body name="LFsrFL_frame" pos="0.07025 0.0299 -0.04511">
                                            <inertial pos="0 0 0" mass="2e-06" diaginertia="1.1e-09 1.1e-09 1.1e-09"/>
                                            <geom size="0.005 0.005 0.0025" type="box"/>
                                        </body>
                                        <body name="LFsrRL_frame" pos="-0.03025 0.0299 -0.04511">
                                            <inertial pos="0 0 0" mass="2e-06" diaginertia="1.1e-09 1.1e-09 1.1e-09"/>
                                            <geom size="0.005 0.005 0.0025" type="box"/>
                                        </body>
                                        <body name="LFootBumperLeft_frame" pos="0.0876 0.019 -0.0353">
                                            <inertial pos="0.0876 0.019 -0.0353" mass="0.001"
                                                      diaginertia="0.001 0.001 0.001"/>
                                        </body>
                                    </body>
                                </body>
                            </body>
                        </body>
                    </body>
                </body>
                <body name="RPelvis" pos="0 -0.05 -0.085">
                    <inertial pos="-0.00781 0.01114 0.02661" quat="-0.286295 0.637526 -0.200888 0.686469" mass="0.06981"
                              diaginertia="6.0003e-05 4.60859e-05 3.15895e-05"/>
                    <joint name="RHipYawPitch" pos="0 0 0" axis="0 0.707107 0.707107" limited="true"
                           range="-1.14529 0.740718"/>
                                        <geom type="mesh" mesh="RHipYawPitch"/>
                    <body name="RHip" pos="0 0 0">
                        <inertial pos="-0.01549 -0.00029 -0.00515" quat="0.431269 0.573083 0.528698 0.453941"
                                  mass="0.14053" diaginertia="6.08554e-05 5.59208e-05 2.2268e-05"/>
                        <joint name="RHipRoll" pos="0 0 0" axis="1 0 0" limited="true" range="-0.79046 0.379435"/>
                                                <geom type="mesh" mesh="RHipRoll"/>
                        <body name="RThigh" pos="0 0 0">
                            <inertial pos="0.00138 -0.00221 -0.05373" quat="0.99203 0.0205489 -0.124311 0.000726212"
                                      mass="0.38968" diaginertia="0.000525121 0.000466802 0.000286518"/>
                            <joint name="RHipPitch" pos="0 0 0" axis="0 1 0" limited="true" range="-1.53589 0.48398"/>
                                                        <geom type="mesh" mesh="RHipPitch"/>
                            <body name="RTibia" pos="0 0 -0.1">
                                <inertial pos="0.00453 -0.00225 -0.04936" quat="0.99698 -0.0149083 0.0724691 -0.0235809"
                                          mass="0.30142" diaginertia="0.000452851 0.000387699 0.000177824"/>
                                <joint name="RKneePitch" pos="0 0 0" axis="0 1 0" limited="true"
                                       range="-0.0923279 2.11255"/>
                                                                <geom type="mesh" mesh="RKneePitch"/>
                                <body name="RAnklePitch" pos="0 0 -0.1029">
                                    <inertial pos="0.00045 -0.00029 0.00685" quat="0.458219 0.537985 0.54818 0.447332"
                                              mass="0.13416" diaginertia="6.79942e-05 5.56532e-05 3.14175e-05"/>
                                    <joint name="RAnklePitch" pos="0 0 0" axis="0 1 0" limited="true"
                                           range="-1.1863 0.932006"/>
                                                                        <geom type="mesh" mesh="RAnklePitch"/>
                                    <body name="r_ankle" pos="0 0 0">
                                        <inertial pos="0.02542 -0.0033 -0.03239"
                                                  quat="-0.0138333 0.704473 0.00894624 0.709539" mass="0.17184"
                                                  diaginertia="0.000412145 0.000352428 8.68592e-05"/>
                                        <joint name="RAnkleRoll" pos="0 0 0" axis="1 0 0" limited="true"
                                               range="-0.768992 0.397761"/>
                                                                                <geom type="mesh" mesh="RAnkleRoll"/>
                                        <body name="r_sole" pos="0 0 -0.04511">
                                            <inertial pos="0 0 -0.04511" mass="0.001" diaginertia="0.001 0.001 0.001"/>
                                        </body>
                                        <body name="RFsrRL_frame" pos="-0.03025 0.0191 -0.04511">
                                            <inertial pos="0 0 0" mass="2e-06" diaginertia="1.1e-09 1.1e-09 1.1e-09"/>
                                            <geom size="0.005 0.005 0.0025" type="box"/>
                                        </body>
                                        <body name="RFsrRR_frame" pos="-0.02965 -0.0299 -0.04511">
                                            <inertial pos="0 0 0" mass="2e-06" diaginertia="1.1e-09 1.1e-09 1.1e-09"/>
                                            <geom size="0.005 0.005 0.0025" type="box"/>
                                        </body>
                                        <body name="RFootBumperRight_frame" pos="0.0876 -0.019 -0.0353">
                                            <inertial pos="0.0876 -0.019 -0.0353" mass="0.001"
                                                      diaginertia="0.001 0.001 0.001"/>
                                        </body>
                                        <body name="RFsrFR_frame" pos="0.07025 -0.0299 -0.04511">
                                            <inertial pos="0 0 0" mass="2e-06" diaginertia="1.1e-09 1.1e-09 1.1e-09"/>
                                            <geom size="0.005 0.005 0.0025" type="box"/>
                                        </body>
                                        <body name="RFootBumperLeft_frame" pos="0.0876 0.014 -0.0353">
                                            <inertial pos="0.0876 0.014 -0.0353" mass="0.001"
                                                      diaginertia="0.001 0.001 0.001"/>
                                        </body>
                                        <body name="RFsrFL_frame" pos="0.07025 0.0231 -0.04511">
                                            <inertial pos="0 0 0" mass="2e-06" diaginertia="1.1e-09 1.1e-09 1.1e-09"/>
                                            <geom size="0.005 0.005 0.0025" type="box"/>
                                        </body>
                                    </body>
                                </body>
                            </body>
                        </body>
                    </body>
                </body>
                <body name="LShoulder" pos="0 0.098 0.1">
                    <inertial pos="-0.00165 -0.02663 0.00014" quat="0.353499 0.572853 -0.442525 0.592494" mass="0.09304"
                              diaginertia="2.02186e-05 1.91002e-05 1.30704e-05"/>
                    <joint name="LShoulderPitch" pos="0 0 0" axis="0 1 0" limited="true" range="-2.08567 2.08567"/>
                                        <geom type="mesh" mesh="LShoulderPitch"/>
                    <body name="LBicep" pos="0 0 0">
                        <inertial pos="0.02455 0.00563 0.0033" quat="0.467645 0.46185 0.492756 0.570257" mass="0.15777"
                                  diaginertia="0.00027823 0.000242894 8.25818e-05"/>
                        <joint name="LShoulderRoll" pos="0 0 0" axis="0 0 1" limited="true" range="-0.314159 1.32645"/>
                                                <geom type="mesh" mesh="LShoulderRoll"/>
                        <body name="LElbow" pos="0.105 0.015 0">
                            <inertial pos="-0.02744 0 -0.00014" quat="-0.000545392 0.711779 -0.000696018 0.702403"
                                      mass="0.06483" diaginertia="2.76333e-05 2.66179e-05 5.592e-06"/>
                            <joint name="LElbowYaw" pos="0 0 0" axis="1 0 0" limited="true" range="-2.08567 2.08567"/>
                            <body name="LForeArm" pos="0 0 0">
                                <inertial pos="0.02556 0.00281 0.00076" quat="0.481839 0.619088 0.422287 0.454131"
                                          mass="0.07761" diaginertia="3.9183e-05 3.6083e-05 2.37632e-05"/>
                                <joint name="LElbowRoll" pos="0 0 0" axis="0 0 1" limited="true"
                                       range="-1.54462 -0.0349066"/>
                                                                <geom type="mesh" mesh="LElbowRoll"/>
                                <body name="l_wrist" pos="0.05595 0 0">
                                    <inertial pos="0.03434 -0.00088 0.00308" quat="0.346526 0.607704 0.329318 0.634165"
                                              mass="0.18533" diaginertia="0.000137482 0.000131631 6.85194e-05"/>
                                    <joint name="LWristYaw" pos="0 0 0" axis="1 0 0" limited="true"
                                           range="-1.82387 1.82387"/>
                                                                        <geom type="mesh" mesh="LWristYaw"/>
                                    <body name="l_gripper" pos="0.05775 0 -0.01231">
                                        <inertial pos="0 0 0" mass="2e-06" diaginertia="1.1e-09 1.1e-09 1.1e-09"/>
                                        <joint name="LHand" pos="0 0 0" axis="1 0 0" limited="true" range="0 1"/>
                                    </body>
                                    <body name="LHandTouchLeft_frame" pos="0.032 0.025 0.003"
                                          quat="0.707105 0 0 0.707108">
                                        <inertial pos="0.032 0.025 0.003" quat="0.707105 0 0 0.707108" mass="0.001"
                                                  diaginertia="0.001 0.001 0.001"/>
                                    </body>
                                    <body name="LHandTouchBack_frame" pos="0.038 0 0.025"
                                          quat="-0.707108 1.87637e-06 0.707105 1.87637e-06">
                                        <inertial pos="0.038 0 0.025" quat="-0.707108 1.87637e-06 0.707105 1.87637e-06"
                                                  mass="0.001" diaginertia="0.001 0.001 0.001"/>
                                    </body>
                                    <body name="LHandTouchRight_frame" pos="0.035 -0.025 0.0035"
                                          quat="0.707105 0 0 -0.707108">
                                        <inertial pos="0.035 -0.025 0.0035" quat="0.707105 0 0 -0.707108" mass="0.001"
                                                  diaginertia="0.001 0.001 0.001"/>
                                    </body>
                                    <body name="LFinger21_link" pos="0.06907 -0.01157 -0.00304"
                                          quat="0.672286 0.564114 0.308141 -0.367227">
                                        <inertial pos="0 0 0" mass="2e-06" diaginertia="1.1e-09 1.1e-09 1.1e-09"/>
                                        <joint name="LFinger21" pos="0 0 0" axis="0 0 1"/>
                                                                                <geom type="mesh" mesh="LFinger21"/>
                                        <body name="LFinger22_link" pos="0.01436 0 0" quat="0.877607 0 0 -0.479381">
                                            <inertial pos="0 0 0" mass="2e-06" diaginertia="1.1e-09 1.1e-09 1.1e-09"/>
                                            <joint name="LFinger22" pos="0 0 0" axis="0 0 1"/>
                                                                                        <geom type="mesh" mesh="LFinger22"/>
                                            <body name="LFinger23_link" pos="0.01436 0 0" quat="0.877607 0 0 -0.479381">
                                                <inertial pos="0 0 0" mass="2e-06"
                                                          diaginertia="1.1e-09 1.1e-09 1.1e-09"/>
                                                <joint name="LFinger23" pos="0 0 0" axis="0 0 1"/>
                                                                                                <geom type="mesh" mesh="LFinger23"/>
                                            </body>
                                        </body>
                                    </body>
                                    <body name="LFinger11_link" pos="0.06907 0.01157 -0.00304"
                                          quat="0.564115 0.672285 0.367228 -0.30814">
                                        <inertial pos="0 0 0" mass="2e-06" diaginertia="1.1e-09 1.1e-09 1.1e-09"/>
                                        <joint name="LFinger11" pos="0 0 0" axis="0 0 1"/>
                                                                                <geom type="mesh" mesh="LFinger11"/>
                                        <body name="LFinger12_link" pos="0.01436 0 0" quat="0.877607 0 0 -0.479381">
                                            <inertial pos="0 0 0" mass="2e-06" diaginertia="1.1e-09 1.1e-09 1.1e-09"/>
                                            <joint name="LFinger12" pos="0 0 0" axis="0 0 1"/>
                                                                                        <geom type="mesh" mesh="LFinger12"/>
                                            <body name="LFinger13_link" pos="0.01436 0 0" quat="0.877607 0 0 -0.479381">
                                                <inertial pos="0 0 0" mass="2e-06"
                                                          diaginertia="1.1e-09 1.1e-09 1.1e-09"/>
                                                <joint name="LFinger13" pos="0 0 0" axis="0 0 1"/>
                                                                                                <geom type="mesh" mesh="LFinger13"/>
                                            </body>
                                        </body>
                                    </body>
                                    <body name="LThumb1_link" pos="0.04895 0 -0.02638"
                                          quat="0.706908 -0.70691 0.0167209 0.016721">
                                        <inertial pos="0 0 0" mass="2e-06" diaginertia="1.1e-09 1.1e-09 1.1e-09"/>
                                        <joint name="LThumb1" pos="0 0 0" axis="0 0 1"/>
                                                                                <geom type="mesh" mesh="LThumb1"/>
                                        <body name="LThumb2_link" pos="0.01436 0 0" quat="0.877607 0 0 -0.479381">
                                            <inertial pos="0 0 0" mass="2e-06" diaginertia="1.1e-09 1.1e-09 1.1e-09"/>
                                            <joint name="LThumb2" pos="0 0 0" axis="0 0 1"/>
                                                                                        <geom type="mesh" mesh="LThumb2"/>
                                        </body>
                                    </body>
                                </body>
                            </body>
                        </body>
                    </body>
                </body>
                <body name="RShoulder" pos="0 -0.098 0.1">
                    <inertial pos="-0.00165 0.02663 0.00014" quat="0.572853 0.353499 -0.592494 0.442525" mass="0.09304"
                              diaginertia="2.02186e-05 1.91002e-05 1.30704e-05"/>
                    <joint name="RShoulderPitch" pos="0 0 0" axis="0 1 0" limited="true" range="-2.08567 2.08567"/>
                                        <geom type="mesh" mesh="RShoulderPitch"/>
                    <body name="RBicep" pos="0 0 0">
                        <inertial pos="0.02455 -0.00563 0.0033" quat="0.556969 0.570609 0.359404 0.484788"
                                  mass="0.15777" diaginertia="0.000287934 0.00025515 8.56154e-05"/>
                        <joint name="RShoulderRoll" pos="0 0 0" axis="0 0 1" limited="true" range="-1.32645 0.314159"/>
                                                <geom type="mesh" mesh="RShoulderRoll"/>
                        <body name="RElbow" pos="0.105 -0.015 0">
                            <inertial pos="-0.02744 0 -0.00014" quat="-0.000545392 0.711779 -0.000696018 0.702403"
                                      mass="0.06483" diaginertia="2.76333e-05 2.66179e-05 5.592e-06"/>
                            <joint name="RElbowYaw" pos="0 0 0" axis="1 0 0" limited="true" range="-2.08567 2.08567"/>
                            <body name="RForeArm" pos="0 0 0">
                                <inertial pos="0.02556 -0.00281 0.00076" quat="0.453039 0.428011 0.593606 0.509111"
                                          mass="0.07761" diaginertia="3.92326e-05 3.59586e-05 2.39457e-05"/>
                                <joint name="RElbowRoll" pos="0 0 0" axis="0 0 1" limited="true"
                                       range="0.0349066 1.54462"/>
                                                                <geom type="mesh" mesh="RElbowRoll"/>
                                <body name="r_wrist" pos="0.05595 0 0">
                                    <inertial pos="0.03434 0.00088 0.00308" quat="0.422432 0.617987 0.303847 0.589339"
                                              mass="0.18533" diaginertia="0.000139307 0.000131711 6.66137e-05"/>
                                    <joint name="RWristYaw" pos="0 0 0" axis="1 0 0" limited="true"
                                           range="-1.82387 1.82387"/>
                                                                        <geom type="mesh" mesh="RWristYaw"/>
                                    <body name="r_gripper" pos="0.05775 0 -0.01213">
                                        <inertial pos="0 0 0" mass="2e-06" diaginertia="1.1e-09 1.1e-09 1.1e-09"/>
                                        <joint name="RHand" pos="0 0 0" axis="1 0 0" limited="true" range="0 1"/>
                                    </body>
                                    <body name="RHandTouchRight_frame" pos="0.035 -0.025 0.0035"
                                          quat="0.707105 0 0 -0.707108">
                                        <inertial pos="0.035 -0.025 0.0035" quat="0.707105 0 0 -0.707108" mass="0.001"
                                                  diaginertia="0.001 0.001 0.001"/>
                                    </body>
                                    <body name="RHandTouchBack_frame" pos="0.038 0 0.025"
                                          quat="-0.707108 1.87637e-06 0.707105 1.87637e-06">
                                        <inertial pos="0.038 0 0.025" quat="-0.707108 1.87637e-06 0.707105 1.87637e-06"
                                                  mass="0.001" diaginertia="0.001 0.001 0.001"/>
                                    </body>
                                    <body name="RHandTouchLeft_frame" pos="0.032 0.025 0.003"
                                          quat="0.707105 0 0 0.707108">
                                        <inertial pos="0.032 0.025 0.003" quat="0.707105 0 0 0.707108" mass="0.001"
                                                  diaginertia="0.001 0.001 0.001"/>
                                    </body>
                                    <body name="RFinger21_link" pos="0.06907 -0.01157 -0.00304"
                                          quat="0.672286 0.564114 0.308141 -0.367227">
                                        <inertial pos="0 0 0" mass="2e-06" diaginertia="1.1e-09 1.1e-09 1.1e-09"/>
                                        <joint name="RFinger21" pos="0 0 0" axis="0 0 1"/>
                                                                                <geom type="mesh" mesh="RFinger21"/>
                                        <body name="RFinger22_link" pos="0.01436 0 0" quat="0.877607 0 0 -0.479381">
                                            <inertial pos="0 0 0" mass="2e-06" diaginertia="1.1e-09 1.1e-09 1.1e-09"/>
                                            <joint name="RFinger22" pos="0 0 0" axis="0 0 1"/>
                                                                                        <geom type="mesh" mesh="RFinger22"/>
                                            <body name="RFinger23_link" pos="0.01436 0 0" quat="0.877607 0 0 -0.479381">
                                                <inertial pos="0 0 0" mass="2e-06"
                                                          diaginertia="1.1e-09 1.1e-09 1.1e-09"/>
                                                <joint name="RFinger23" pos="0 0 0" axis="0 0 1"/>
                                                                                                <geom type="mesh" mesh="RFinger23"/>
                                            </body>
                                        </body>
                                    </body>
                                    <body name="RFinger11_link" pos="0.06907 0.01157 -0.00304"
                                          quat="0.564115 0.672285 0.367228 -0.30814">
                                        <inertial pos="0 0 0" mass="2e-06" diaginertia="1.1e-09 1.1e-09 1.1e-09"/>
                                        <joint name="RFinger11" pos="0 0 0" axis="0 0 1"/>
                                                                                <geom type="mesh" mesh="RFinger11"/>
                                        <body name="RFinger12_link" pos="0.01436 0 0" quat="0.877607 0 0 -0.479381">
                                            <inertial pos="0 0 0" mass="2e-06" diaginertia="1.1e-09 1.1e-09 1.1e-09"/>
                                            <joint name="RFinger12" pos="0 0 0" axis="0 0 1"/>
                                                                                        <geom type="mesh" mesh="RFinger12"/>
                                            <body name="RFinger13_link" pos="0.01436 0 0" quat="0.877607 0 0 -0.479381">
                                                <inertial pos="0 0 0" mass="2e-06"
                                                          diaginertia="1.1e-09 1.1e-09 1.1e-09"/>
                                                <joint name="RFinger13" pos="0 0 0" axis="0 0 1"/>
                                                                                                <geom type="mesh" mesh="RFinger13"/>
                                            </body>
                                        </body>
                                    </body>
                                    <body name="RThumb1_link" pos="0.04895 0 -0.02638"
                                          quat="0.706908 -0.70691 0.0167209 0.016721">
                                        <inertial pos="0 0 0" mass="2e-06" diaginertia="1.1e-09 1.1e-09 1.1e-09"/>
                                        <joint name="RThumb1" pos="0 0 0" axis="0 0 1"/>
                                                                                <geom type="mesh" mesh="RThumb1"/>
                                        <body name="RThumb2_link" pos="0.01436 0 0" quat="0.877607 0 0 -0.479381">
                                            <inertial pos="0 0 0" mass="2e-06" diaginertia="1.1e-09 1.1e-09 1.1e-09"/>
                                            <joint name="RThumb2" pos="0 0 0" axis="0 0 1"/>
                                                                                        <geom type="mesh" mesh="RThumb2"/>
                                        </body>
                                    </body>
                                </body>
                            </body>
                        </body>
                    </body>
                </body>
                <body name="ImuTorsoAccelerometer_frame" pos="-0.008 0.00606 0.027">
                    <inertial pos="-0.008 0.00606 0.027" mass="0.001" diaginertia="0.001 0.001 0.001"/>
                </body>
                <body name="RSonar_frame" pos="0.00558253 -0.0192068 0.0623853"
                      quat="0.980564 0.00660077 0.0209379 -0.194968">
                    <inertial pos="0.00558253 -0.0192068 0.0623853" quat="0.980564 0.00660077 0.0209379 -0.194968"
                              mass="0.001" diaginertia="0.001 0.001 0.001"/>
                </body>
                <body name="LSonar_frame" pos="0.00558253 0.0192068 0.0623853"
                      quat="0.980564 -0.00660077 0.0209379 0.194968">
                    <inertial pos="0.00558253 0.0192068 0.0623853" quat="0.980564 -0.00660077 0.0209379 0.194968"
                              mass="0.001" diaginertia="0.001 0.001 0.001"/>
                </body>
                <body name="ImuTorsoGyrometer_frame" pos="-0.008 0.006 0.029">
                    <inertial pos="-0.008 0.006 0.029" mass="0.001" diaginertia="0.001 0.001 0.001"/>
                </body>
                <body name="ChestButton_frame" pos="0.049871 0.001588 0.055163">
                    <inertial pos="0.049871 0.001588 0.055163" mass="0.001" diaginertia="0.001 0.001 0.001"/>
                </body>
            </body>
        </body>
    </worldbody>
    <actuator>
        <motor ctrllimited="true" ctrlrange="-1.0 1.0" joint="HeadYaw" gear="10"/>
        <motor ctrllimited="true" ctrlrange="-1.0 1.0" joint="HeadPitch" gear="10"/>
        <motor ctrllimited="true" ctrlrange="-1.0 1.0" joint="LHipYawPitch" gear="10"/>
        <motor ctrllimited="true" ctrlrange="-1.0 1.0" joint="LHipRoll" gear="10"/>
        <motor ctrllimited="true" ctrlrange="-1.0 1.0" joint="LHipPitch" gear="10"/>
        <motor ctrllimited="true" ctrlrange="-1.0 1.0" joint="LKneePitch" gear="10"/>
        <motor ctrllimited="true" ctrlrange="-1.0 1.0" joint="LAnklePitch" gear="10"/>
        <motor ctrllimited="true" ctrlrange="-1.0 1.0" joint="LAnkleRoll" gear="10"/>
        <motor ctrllimited="true" ctrlrange="-1.0 1.0" joint="RHipYawPitch" gear="10"/>
        <motor ctrllimited="true" ctrlrange="-1.0 1.0" joint="RHipRoll" gear="10"/>
        <motor ctrllimited="true" ctrlrange="-1.0 1.0" joint="RHipPitch" gear="10"/>
        <motor ctrllimited="true" ctrlrange="-1.0 1.0" joint="RKneePitch" gear="10"/>
        <motor ctrllimited="true" ctrlrange="-1.0 1.0" joint="RAnklePitch" gear="10"/>
        <motor ctrllimited="true" ctrlrange="-1.0 1.0" joint="RAnkleRoll" gear="10"/>
        <motor ctrllimited="true" ctrlrange="-1.0 1.0" joint="LShoulderPitch" gear="10"/>
        <motor ctrllimited="true" ctrlrange="-1.0 1.0" joint="LShoulderRoll" gear="10"/>
        <motor ctrllimited="true" ctrlrange="-1.0 1.0" joint="LElbowYaw" gear="10"/>
        <motor ctrllimited="true" ctrlrange="-1.0 1.0" joint="LElbowRoll" gear="10"/>
        <motor ctrllimited="true" ctrlrange="-1.0 1.0" joint="LWristYaw" gear="10"/>
        <motor ctrllimited="true" ctrlrange="-1.0 1.0" joint="LHand" gear="10"/>
        <!--    <motor ctrllimited="true" ctrlrange="-1.0 1.0" joint="LFinger21" gear="10"/>-->
        <!--    <motor ctrllimited="true" ctrlrange="-1.0 1.0" joint="LFinger22" gear="10"/>-->
        <!--    <motor ctrllimited="true" ctrlrange="-1.0 1.0" joint="LFinger23" gear="10"/>-->
        <!--    <motor ctrllimited="true" ctrlrange="-1.0 1.0" joint="LFinger11" gear="10"/>-->
        <!--    <motor ctrllimited="true" ctrlrange="-1.0 1.0" joint="LFinger12" gear="10"/>-->
        <!--    <motor ctrllimited="true" ctrlrange="-1.0 1.0" joint="LFinger13" gear="10"/>-->
        <!--    <motor ctrllimited="true" ctrlrange="-1.0 1.0" joint="LThumb1" gear="10"/>-->
        <!--    <motor ctrllimited="true" ctrlrange="-1.0 1.0" joint="LThumb2" gear="10"/>-->
        <motor ctrllimited="true" ctrlrange="-1.0 1.0" joint="RShoulderPitch" gear="10"/>
        <motor ctrllimited="true" ctrlrange="-1.0 1.0" joint="RShoulderRoll" gear="10"/>
        <motor ctrllimited="true" ctrlrange="-1.0 1.0" joint="RElbowYaw" gear="10"/>
        <motor ctrllimited="true" ctrlrange="-1.0 1.0" joint="RElbowRoll" gear="10"/>
        <motor ctrllimited="true" ctrlrange="-1.0 1.0" joint="RWristYaw" gear="10"/>
        <motor ctrllimited="true" ctrlrange="-1.0 1.0" joint="RHand" gear="10"/>
        <!--    <motor ctrllimited="true" ctrlrange="-1.0 1.0" joint="RFinger21" gear="10"/>-->
        <!--    <motor ctrllimited="true" ctrlrange="-1.0 1.0" joint="RFinger22" gear="10"/>-->
        <!--    <motor ctrllimited="true" ctrlrange="-1.0 1.0" joint="RFinger23" gear="10"/>-->
        <!--    <motor ctrllimited="true" ctrlrange="-1.0 1.0" joint="RFinger11" gear="10"/>-->
        <!--    <motor ctrllimited="true" ctrlrange="-1.0 1.0" joint="RFinger12" gear="10"/>-->
        <!--    <motor ctrllimited="true" ctrlrange="-1.0 1.0" joint="RFinger13" gear="10"/>-->
        <!--    <motor ctrllimited="true" ctrlrange="-1.0 1.0" joint="RThumb1" gear="10"/>-->
        <!--    <motor ctrllimited="true" ctrlrange="-1.0 1.0" joint="RThumb2" gear="10"/>-->

    </actuator>

    <sensor>
        <velocimeter name="sensor_velocimeter" site="torso_site"/>
        <gyro name="sensor_gyro" site="torso_site"/>
        <accelerometer name="sensor_accel" site="torso_site"/>
        <rangefinder name="sensor_rangefinder_torso" site="rangefinder_torso"/>
    </sensor>

</mujoco>
